<?xml version="1.0" encoding="utf-8"?>
<!-- This URDF was automatically created by SolidWorks to URDF Exporter! Originally created by Stephen Brawner (brawner@gmail.com) 
     Commit Version: 1.6.0-4-g7f85cfe  Build Version: 1.6.7995.38578
     For more information, please see http://wiki.ros.org/sw_urdf_exporter -->
<robot
  name="T1">
  <!-- <mujoco>
    <compiler meshdir="meshes/" balanceinertia="true" discardvisual="false"/>
  </mujoco> -->
  <!-- for convert to mujoco
  <link name="world"/>
  <joint name="world_joint" type="floating">
    <origin xyz="0 0 0"/>
    <parent link="world"/>
    <child link="Trunk"/>
  </joint>
  -->
  <link
    name="Trunk">
    <inertial>
      <origin
        xyz="0.0551365401093076 -1.42058017623659E-06 0.105062332707657"
        rpy="0 0 0" />
      <mass
        value="11.7" />
      <inertia
        ixx="0.0915287235057927"
        ixy="-4.25369739206781E-07"
        ixz="0.000646360369011163"
        iyy="0.076778716903413"
        iyz="5.82340020271393E-07"
        izz="0.0556171053368987" />
    </inertial>
    <visual>
      <origin
        xyz="0 0 0"
        rpy="0 0 0" />
      <geometry>
        <mesh
          filename="meshes/Trunk.STL" />
      </geometry>
      <material
        name="">
        <color
          rgba="0.76 0.76 0.76 0.2" />
      </material>
    </visual>
    <visual>
      <origin
        xyz="0 0 0"
        rpy="0 0 0" />
      <geometry>
        <mesh
          filename="meshes/Logo.STL" />
      </geometry>
      <material
        name="">
        <color
          rgba="0.69804 0.69804 0.69804 1" />
      </material>
    </visual>    
    <collision>
      <origin
        xyz="0.06 0 0.12"
        rpy="0 0 0" />
      <geometry>
        <box size="0.17 0.18 0.29" />
      </geometry>
    </collision>
  </link>
  <link
    name="H1">
    <inertial>
      <origin
        xyz="-0.000508 -0.001403 0.057432"
        rpy="0 0 0" />
      <mass
        value="0.443910" />
      <inertia
        ixx="0.000224"
        ixy="0.000003"
        ixz="0.000001"
        iyy="0.000241"
        iyz="-0.000002"
        izz="0.000150" />
    </inertial>
    <visual>
      <origin
        xyz="0 0 0"
        rpy="0 0 0" />
      <geometry>
        <mesh
          filename="meshes/H1.STL" />
      </geometry>
      <material
        name="">
        <color
          rgba="0.4 0.4 0.4 0.3" />
      </material>
    </visual>
    <collision>
      <origin
        xyz="0 0 0.06"
        rpy="1.5708 0 0" />
      <geometry>
        <cylinder radius="0.025" length="0.07" />
      </geometry>
    </collision>
  </link>
  <joint
    name="AAHead_yaw"
    type="revolute">
    <origin
      xyz="0.0625 0 0.243"
      rpy="0 0 0" />
    <parent
      link="Trunk" />
    <child
      link="H1" />
    <axis
      xyz="0 0 1" />
    <limit
      lower="-1.0472"
      upper="1.0472"
      effort="7"
      velocity="12.56" />
  </joint>
  <link
    name="H2">
    <inertial>
      <origin
        xyz="0.007802 0.001262 0.098631"
        rpy="0 0 0" />
      <mass
        value="0.631019" />
      <inertia
        ixx="0.002025"
        ixy="-0.000025"
        ixz="0.000046"
        iyy="0.001920"
        iyz="0.000036"
        izz="0.001739" />
    </inertial>
    <visual>
      <origin
        xyz="0 0 0"
        rpy="0 0 0" />
      <geometry>
        <mesh
          filename="meshes/H2.STL" />
      </geometry>
      <material
        name="">
        <color
          rgba="0.4 0.4 0.4 0.3" />
      </material>
    </visual>
    <collision>
      <origin
        xyz="0.01 0 0.11"
        rpy="0 0 0" />
      <geometry>
        <sphere radius="0.08" />
      </geometry>
    </collision>
  </link>
  <joint
    name="Head_pitch"
    type="revolute">
    <origin
      xyz="0 0 0.06185"
      rpy="0 0 0" />
    <parent
      link="H1" />
    <child
      link="H2" />
    <axis
      xyz="0 1 0" />
    <limit
      lower="-0.3491"
      upper="0.8552"
      effort="7"
      velocity="12.56" />
  </joint>
  <link
    name="AL1">
    <inertial>
      <origin
        xyz="-0.000677 0.044974 0.000000"
        rpy="0 0 0" />
      <mass
        value="0.53" />
      <inertia
        ixx="0.001293"
        ixy="-0.000017"
        ixz="0.000000"
        iyy="0.000293"
        iyz="0.000000"
        izz="0.001367" />
    </inertial>
    <visual>
      <origin
        xyz="0 0 0"
        rpy="0 0 0" />
      <geometry>
        <mesh
          filename="meshes/AL1.STL" />
      </geometry>
      <material
        name="">
        <color
          rgba="0.76 0.76 0.76 0.2" />
      </material>
    </visual>
    <collision>
      <origin
        xyz="0 0.047 0"
        rpy="0 1.5708 0" />
      <geometry>
        <cylinder radius="0.03" length="0.07" />
      </geometry>
    </collision>
  </link>
  <joint
    name="Left_Shoulder_Pitch"
    type="revolute">
    <origin
      xyz="0.0575 0.1063 0.219"
      rpy="0 0.00088113 0" />
    <parent
      link="Trunk" />
    <child
      link="AL1" />
    <axis
      xyz="0 1 0" />
    <limit
      lower="-3.29"
      upper="1.18"
      effort="18"
      velocity="18" />
  </joint>
  <link
    name="AL2">
    <inertial>
      <origin
        xyz="0.003862 0.037976 0.000000"
        rpy="0 0 0" />
      <mass
        value="0.160" />
      <inertia
        ixx="0.000345"
        ixy="0.000008"
        ixz="0.000000"
        iyy="0.000177"
        iyz="0.000000"
        izz="0.000401" />
    </inertial>
    <visual>
      <origin
        xyz="0 0 0"
        rpy="0 0 0" />
      <geometry>
        <mesh
          filename="meshes/AL2.STL" />
      </geometry>
      <material
        name="">
        <color
          rgba="0.4 0.4 0.4 0.3" />
      </material>
    </visual>
  </link>
  <joint
    name="Left_Shoulder_Roll"
    type="revolute">
    <origin
      xyz="0 0.047 0"
      rpy="0 0 0" />
    <parent
      link="AL1" />
    <child
      link="AL2" />
    <axis
      xyz="1 0 0" />
    <limit
      lower="-1.577"
      upper="1.7055"
      effort="18"
      velocity="18" />
  </joint>
  <link
    name="AL3">
    <inertial>
      <origin
        xyz="0.000000 0.085353 -0.000099"
        rpy="0 0 0" />
      <mass
        value="1.02" />
      <inertia
        ixx="0.012869"
        ixy="0.000000"
        ixz="0.000000"
        iyy="0.000621"
        iyz="-0.000024"
        izz="0.012798" />
    </inertial>
    <visual>
      <origin
        xyz="0 0 0"
        rpy="0 0 0" />
      <geometry>
        <mesh
          filename="meshes/AL3.STL" />
      </geometry>
      <material
        name="">
        <color
          rgba="0.4 0.4 0.4 0.3" />
      </material>
    </visual>
    <collision>
      <origin
        xyz="0 0.07 0"
        rpy="1.5708 0 0" />
      <geometry>
        <cylinder radius="0.03" length="0.19" />
      </geometry>
    </collision>
  </link>
  <joint
    name="Left_Elbow_Pitch"
    type="revolute">
    <origin
      xyz="0.00025 0.0605 0"
      rpy="0 0 0" />
    <parent
      link="AL2" />
    <child
      link="AL3" />
    <axis
      xyz="0 1 0" />
    <limit
      lower="-2.234"
      upper="2.234"
      effort="18"
      velocity="18" />
  </joint>
  <link
    name="AL4">
    <inertial>
      <origin
        xyz="-0.00046851 0.062372 0.0015178"
        rpy="0 0 0" />
      <mass
        value="0.5570" />
      <inertia
        ixx="0.001673"
        ixy="-1.2E-05"
        ixz="0"
        iyy="0.000214"
        iyz="4E-06"
        izz="0.001608" />
    </inertial>
    <collision>
      <origin
        xyz="0 0.08 0"
        rpy="1.5708 0 0" />
      <geometry>
        <cylinder radius="0.04" length="0.14" />
      </geometry>
    </collision>
    <visual>
      <origin
        xyz="0 0 0"
        rpy="0 0 0" />
      <geometry>
        <mesh
          filename="meshes/AL4.STL" />
      </geometry>
      <material
        name="">
        <color
          rgba="0.75294 0.75294 0.75294 1" />
      </material>
    </visual>
  </link>
  <joint
    name="Left_Elbow_Yaw"
    type="revolute">
    <origin
      xyz="0 0.1471 0"
      rpy="0 0 0" />
    <parent
      link="AL3" />
    <child
      link="AL4" />
    <axis
      xyz="0 0 1" />
    <limit
      lower="-2.1402"
      upper="1.6844"
      effort="18"
      velocity="18" />
  </joint>
  <link
    name="AL5">
    <inertial>
      <origin
        xyz="-3.8402E-05 0.036076 0.0056711"
        rpy="0 0 0" />
      <mass
        value="0.43402" />
      <inertia
        ixx="0.000823"
        ixy="0"
        ixz="0"
        iyy="0.000216"
        iyz="9.8E-05"
        izz="0.000785" />
    </inertial>
    <visual>
      <origin
        xyz="0 0 0"
        rpy="0 0 0" />
      <geometry>
        <mesh
          filename="meshes/AL5.STL" />
      </geometry>
      <material
        name="">
        <color
          rgba="0.75294 0.75294 0.75294 1" />
      </material>
    </visual>
  </link>
  <joint
    name="Left_Wrist_Pitch"
    type="revolute">
    <origin
      xyz="0 0.105 0.00025"
      rpy="0 0 0" />
    <parent
      link="AL4" />
    <child
      link="AL5" />
    <axis
      xyz="0 1 0" />
    <limit
      lower="-2.5821"
      upper="2.5821"
      effort="7"
      velocity="12.56" />
  </joint>
  <link
    name="AL6">
    <inertial>
      <origin
        xyz="-0.00072939 0.056578 -0.0056257"
        rpy="0 0 0" />
      <mass
        value="0.47922" />
      <inertia
        ixx="0.001171"
        ixy="-1.5E-05"
        ixz="-1E-06"
        iyy="0.000166"
        iyz="-1.5E-05"
        izz="0.001138" />
    </inertial>
    <visual>
      <origin
        xyz="0 0 0"
        rpy="0 0 0" />
      <geometry>
        <mesh
          filename="meshes/AL6.STL" />
      </geometry>
      <material
        name="">
        <color
          rgba="0.75294 0.75294 0.75294 1" />
      </material>
    </visual>
  </link>
  <joint
    name="Left_Wrist_Yaw"
    type="revolute">
    <origin
      xyz="0 0.042 0"
      rpy="0 0 0" />
    <parent
      link="AL5" />
    <child
      link="AL6" />
    <axis
      xyz="0 0 1" />
    <limit
      lower="-1.8185"
      upper="1.4261"
      effort="18"
      velocity="18" />
  </joint>
  <link
    name="left_hand_link">
    <inertial>
      <origin
        xyz="-0.0067917 0.06373 0.011867"
        rpy="0 0 0" />
      <mass
        value="0.30603" />
      <inertia
        ixx="0.002302"
        ixy="0.000002"
        ixz="0.000000"
        iyy="0.000307"
        iyz="-0.000108"
        izz="0.002439" />
    </inertial>
    <collision>
      <origin
        xyz="0 0.1 0"
        rpy="1.5708 0 0" />
      <geometry>
        <cylinder radius="0.06" length="0.15" />
      </geometry>
    </collision>
    <visual>
      <origin
        xyz="0 0 0"
        rpy="0 0 0" />
      <geometry>
        <mesh
          filename="meshes/AL7.STL" />
      </geometry>
      <material
        name="">
        <color
          rgba="0.75294 0.75294 0.75294 1" />
      </material>
    </visual>
  </link>
  <joint
    name="Left_Hand_Roll"
    type="revolute">
    <origin
      xyz="0.00475 0.07 0.0015"
      rpy="0 0 0" />
    <parent
      link="AL6" />
    <child
      link="left_hand_link" />
    <axis
      xyz="1 0 0" />
    <limit
      lower="-0.758"
      upper="1.4285"
      effort="7"
      velocity="12.56" />
  </joint>
  <link
    name="AR1">
    <inertial>
      <origin
        xyz="-0.000677 -0.044974 0.000000"
        rpy="0 0 0" />
      <mass
        value="0.53" />
      <inertia
        ixx="0.001293"
        ixy="-0.000017"
        ixz="0.000000"
        iyy="0.000293"
        iyz="0.000000"
        izz="0.001367" />
    </inertial>
    <visual>
      <origin
        xyz="0 0 0"
        rpy="0 0 0" />
      <geometry>
        <mesh
          filename="meshes/AR1.STL" />
      </geometry>
      <material
        name="">
        <color
          rgba="0.76 0.76 0.76 0.2" />
      </material>
    </visual>
    <collision>
      <origin
        xyz="0 -0.047 0"
        rpy="0 1.5708 0" />
      <geometry>
        <cylinder radius="0.03" length="0.07" />
      </geometry>
    </collision>
  </link>
  <joint
    name="Right_Shoulder_Pitch"
    type="revolute">
    <origin
      xyz="0.0575 -0.1063 0.219"
      rpy="0 0.00088113 0" />
    <parent
      link="Trunk" />
    <child
      link="AR1" />
    <axis
      xyz="0 1 0" />
    <limit
      lower="-3.29"
      upper="1.1868"
      effort="18"
      velocity="18" />
  </joint>
  <link
    name="AR2">
    <inertial>
      <origin
        xyz="0.003862 -0.037976 0.000000"
        rpy="0 0 0" />
      <mass
        value="0.160" />
      <inertia
        ixx="0.000345"
        ixy="-0.000008"
        ixz="0.000000"
        iyy="0.000177"
        iyz="0.000000"
        izz="0.000401" />
    </inertial>
    <visual>
      <origin
        xyz="0 0 0"
        rpy="0 0 0" />
      <geometry>
        <mesh
          filename="meshes/AR2.STL" />
      </geometry>
      <material
        name="">
        <color
          rgba="0.4 0.4 0.4 0.3" />
      </material>
    </visual>
  </link>
  <joint
    name="Right_Shoulder_Roll"
    type="revolute">
    <origin
      xyz="0 -0.047 0"
      rpy="0 0 0" />
    <parent
      link="AR1" />
    <child
      link="AR2" />
    <axis
      xyz="1 0 0" />
    <limit
      lower="-1.7055"
      upper="1.577"
      effort="18"
      velocity="18" />
  </joint>
  <link
    name="AR3">
    <inertial>
      <origin  
        xyz="0.000000 -0.085353 -0.000099"
        rpy="0 0 0" />
      <mass
        value="1.02" />
      <inertia
        ixx="0.012869"
        ixy="0.000000"
        ixz="0.000000"
        iyy="0.000621"
        iyz="0.000024"
        izz="0.012798" />
    </inertial>
    <visual>
      <origin
        xyz="0 0 0"
        rpy="0 0 0" />
      <geometry>
        <mesh
          filename="meshes/AR3.STL" />
      </geometry>
      <material
        name="">
        <color
          rgba="0.4 0.4 0.4 0.3" />
      </material>
    </visual>
    <collision>
      <origin
        xyz="0 -0.07 0"
        rpy="1.5708 0 0" />
      <geometry>
        <cylinder radius="0.03" length="0.19" />
      </geometry>
    </collision>
  </link>
  <joint
    name="Right_Elbow_Pitch"
    type="revolute">
    <origin
      xyz="0.00025 -0.0605 0"
      rpy="0 0 0" />
    <parent
      link="AR2" />
    <child
      link="AR3" />
    <axis
      xyz="0 1 0" />
    <limit
      lower="-2.234"
      upper="2.234"
      effort="18"
      velocity="18" />
  </joint>
  <link
    name="AR4">
    <inertial>
      <origin
        xyz="-0.0004573 -0.067734 0.0017465"
        rpy="0 0 0" />
      <mass
        value="0.5570" />
      <inertia
        ixx="0.002292"
        ixy="1.4E-05"
        ixz="0"
        iyy="0.000234"
        iyz="-5E-06"
        izz="0.002223" />
    </inertial>
    <collision>
      <origin
        xyz="0 -0.08 0"
        rpy="1.5708 0 0" />
      <geometry>
        <cylinder radius="0.04" length="0.14" />
      </geometry>
    </collision>
    <visual>
      <origin
        xyz="0 0 0"
        rpy="0 0 0" />
      <geometry>
        <mesh
          filename="meshes/AR4.STL" />
      </geometry>
      <material
        name="">
        <color
          rgba="0.75294 0.75294 0.75294 1" />
      </material>
    </visual>
  </link>
  <joint
    name="Right_Elbow_Yaw"
    type="revolute">
    <origin
      xyz="0 -0.1471 0"
      rpy="0 0 0" />
    <parent
      link="AR3" />
    <child
      link="AR4" />
    <axis
      xyz="0 0 1" />
    <limit
      lower="-1.6844"
      upper="2.1402"
      effort="18"
      velocity="18" />
  </joint>
  <link
    name="AR5">
    <inertial>
      <origin
        xyz="3.7355E-05 -0.035638 0.0053147"
        rpy="0 0 0" />
      <mass
        value="0.43402" />
      <inertia
        ixx="0.000836"
        ixy="0"
        ixz="0"
        iyy="0.00022"
        iyz="-9.5E-05"
        izz="0.000797" />
    </inertial>
    <visual>
      <origin
        xyz="0 0 0"
        rpy="0 0 0" />
      <geometry>
        <mesh
          filename="meshes/AR5.STL" />
      </geometry>
      <material
        name="">
        <color
          rgba="0.75294 0.75294 0.75294 1" />
      </material>
    </visual>
  </link>
  <joint
    name="Right_Wrist_Pitch"
    type="revolute">
    <origin
      xyz="0 -0.105 0.00025"
      rpy="0 0 0" />
    <parent
      link="AR4" />
    <child
      link="AR5" />
    <axis
      xyz="0 1 0" />
    <limit
      lower="-2.5821"
      upper="2.5821"
      effort="7"
      velocity="12.56" />
  </joint>
  <link
    name="AR6">
    <inertial>
      <origin
        xyz="-0.0011437 -0.056205 -0.0056621"
        rpy="0 0 0" />
      <mass
        value="0.47922" />
      <inertia
        ixx="0.001238"
        ixy="2.4E-05"
        ixz="-1E-06"
        iyy="0.000182"
        iyz="1.4E-05"
        izz="0.00121" />
    </inertial>
    <visual>
      <origin
        xyz="0 0 0"
        rpy="0 0 0" />
      <geometry>
        <mesh
          filename="meshes/AR6.STL" />
      </geometry>
      <material
        name="">
        <color
          rgba="0.75294 0.75294 0.75294 1" />
      </material>
    </visual>
  </link>
  <joint
    name="Right_Wrist_Yaw"
    type="revolute">
    <origin
      xyz="0 -0.042 0"
      rpy="0 0 0" />
    <parent
      link="AR5" />
    <child
      link="AR6" />
    <axis
      xyz="0 0 1" />
    <limit
      lower="-1.4261"
      upper="1.8185"
      effort="18"
      velocity="18" />
  </joint>
  <link
    name="right_hand_link">
    <inertial>
      <origin
        xyz="-0.0047758 -0.064411 0.011992"
        rpy="0 0 0" />
      <mass
        value="0.30603" />
      <inertia
        ixx="0.002287"
        ixy="-0.000002"
        ixz="0.000000"
        iyy="0.000292"
        iyz="-0.000102"
        izz="0.002418" />
    </inertial>
    <collision>
      <origin
        xyz="0 -0.1 0"
        rpy="1.5708 0 0" />
      <geometry>
        <cylinder radius="0.06" length="0.15" />
      </geometry>
    </collision>
    <visual>
      <origin
        xyz="0 0 0"
        rpy="0 0 0" />
      <geometry>
        <mesh
          filename="meshes/AR7.STL" />
      </geometry>
      <material
        name="">
        <color
          rgba="0.75294 0.75294 0.75294 1" />
      </material>
    </visual>
  </link>
  <joint
    name="Right_Hand_Roll"
    type="revolute">
    <origin
      xyz="0.00475 -0.07 0.0015"
      rpy="0 0 0" />
    <parent
      link="AR6" />
    <child
      link="right_hand_link" />
    <axis
      xyz="1 0 0" />
    <limit
      lower="-1.4285"
      upper="0.758"
      effort="7"
      velocity="12.56" />
  </joint>

  <link
    name="Waist">
    <inertial>
      <origin
        xyz="0.002284 0.000003 0.007301"
        rpy="0 0 0" />
      <mass
        value="2.581" />
      <inertia
        ixx="0.005289"
        ixy="0.000000"
        ixz="0.000207"
        iyy="0.005299"
        iyz="0.000001"
        izz="0.004821" />
    </inertial>
    <visual>
      <origin
        xyz="0 0 0"
        rpy="0 0 0" />
      <geometry>
        <mesh
          filename="meshes/Waist.STL" />
      </geometry>
      <material
        name="">
        <color
          rgba="0.4 0.4 0.4 0.3" />
      </material>
    </visual>
    <collision>
      <origin
        xyz="0 0 0"
        rpy="1.5708 0 0" />
      <geometry>
        <cylinder radius="0.06" length="0.1" />
      </geometry>
    </collision>
  </link>
  <joint
    name="Waist"
    type="revolute">
    <origin
      xyz="0.0625 0 -0.1155"
      rpy="0 0 0" />
    <parent
      link="Trunk" />
    <child
      link="Waist" />
    <axis
      xyz="0 0 1" />
    <limit
      lower="-1.57"
      upper="1.57"
      effort="25"
      velocity="7.1" />
  </joint>
  <link
    name="Hip_Pitch_Left">
    <inertial>
      <origin
        xyz="0.000534 -0.007296 -0.018083"
        rpy="0 0 0" />
      <mass
        value="1.021" />
      <inertia
        ixx="0.001805"
        ixy="0.000006"
        ixz="-0.000015"
        iyy="0.001421"
        iyz="0.000080"
        izz="0.001292" />
    </inertial>
    <visual>
      <origin
        xyz="0 0 0"
        rpy="0 0 0" />
      <geometry>
        <mesh
          filename="meshes/Hip_Pitch_Left.STL" />
      </geometry>
      <material
        name="">
        <color
          rgba="0.76 0.76 0.76 0.2" />
      </material>
    </visual>
    <collision>
      <origin
        xyz="-0.002 0 -0.02"
        rpy="0 1.5708 0" />
      <geometry>
        <cylinder radius="0.045" length="0.085" />
      </geometry>
    </collision>
  </link>
  <joint
    name="Left_Hip_Pitch"
    type="revolute">
    <origin
      xyz="0 0.106 0"
      rpy="0 0 0" />
    <parent
      link="Waist" />
    <child
      link="Hip_Pitch_Left" />
    <axis
      xyz="0 1 0" />
    <limit
      lower="-3.0020"
      upper="2.2166"
      effort="45"
      velocity="15.2" />
  </joint>
  <link
    name="Hip_Roll_Left">
    <inertial>
      <origin
        xyz="0.001101 0.000024 -0.053750"
        rpy="0 0 0" />
      <mass
        value="0.385" />
      <inertia
        ixx="0.001517"
        ixy="0.000000"
        ixz="0.000017"
        iyy="0.001743"
        iyz="0.000000"
        izz="0.000515" />
    </inertial>
    <visual>
      <origin
        xyz="0 0 0"
        rpy="0 0 0" />
      <geometry>
        <mesh
          filename="meshes/Hip_Roll_Left.STL" />
      </geometry>
      <material
        name="">
        <color
          rgba="0.4 0.4 0.4 0.3" />
      </material>
    </visual>
    <collision>
      <origin
        xyz="0 0 -0.11"
        rpy="0 0 0" />
      <geometry>
        <cylinder radius="0.045" length="0.08" />
      </geometry>
    </collision>
  </link>
  <joint
    name="Left_Hip_Roll"
    type="revolute">
    <origin
      xyz="0 0 -0.02"
      rpy="0 0 0" />
    <parent
      link="Hip_Pitch_Left" />
    <child
      link="Hip_Roll_Left" />
    <axis
      xyz="1 0 0" />
    <limit
      lower="-0.2"
      upper="1.57"
      effort="25"
      velocity="7.1" />
  </joint>
  <link
    name="Hip_Yaw_Left">
    <inertial>
      <origin
        xyz="-0.007233 0.000206 -0.089184"
        rpy="0 0 0" />
      <mass
        value="2.166" />
      <inertia
        ixx="0.025108"
        ixy="-0.000007"
        ixz="0.002094"
        iyy="0.025733"
        iyz="-0.000050"
        izz="0.002787" />
    </inertial>
    <visual>
      <origin
        xyz="0 0 0"
        rpy="0 0 0" />
      <geometry>
        <mesh
          filename="meshes/Hip_Yaw_Left.STL" />
      </geometry>
      <material
        name="">
        <color
          rgba="0.4 0.4 0.4 0.3" />
      </material>
    </visual>
    <collision>
      <origin
        xyz="-0.015 0 -0.135"
        rpy="1.5708 0 0" />
      <geometry>
        <cylinder radius="0.055" length="0.09" />
      </geometry>
    </collision>
  </link>
  <joint
    name="Left_Hip_Yaw"
    type="revolute">
    <origin
      xyz="0 0 -0.081854"
      rpy="0 0 0" />
    <parent
      link="Hip_Roll_Left" />
    <child
      link="Hip_Yaw_Left" />
    <axis
      xyz="0 0 1" />
    <limit
      lower="-1"
      upper="1"
      effort="25"
      velocity="7.1" />
  </joint>
  <link
    name="Shank_Left">
    <inertial>
      <origin
        xyz="-0.006012 0.000259 -0.124318"
        rpy="0 0 0" />
      <mass
        value="1.82" />
      <inertia
        ixx="0.034618"
        ixy="0.000011"
        ixz="0.001561"
        iyy="0.034539"
        iyz="0.000197"
        izz="0.001934" />
    </inertial>
    <visual>
      <origin
        xyz="0 0 0"
        rpy="0 0 0" />
      <geometry>
        <mesh
          filename="meshes/Shank_Left.STL" />
      </geometry>
      <material
        name="">
        <color
          rgba="0.4 0.4 0.4 0.3" />
      </material>
    </visual>
    <collision>
      <origin
        xyz="0 0 -0.15"
        rpy="0 0 0" />
      <geometry>
        <box size="0.1 0.08 0.14" />
      </geometry>
    </collision>
  </link>
  <joint
    name="Left_Knee_Pitch"
    type="revolute">
    <origin
      xyz="-0.014 0 -0.134"
      rpy="0 0 0" />
    <parent
      link="Hip_Yaw_Left" />
    <child
      link="Shank_Left" />
    <axis
      xyz="0 1 0" />
    <limit
      lower="0"
      upper="2.1817"
      effort="60"
      velocity="14.7" />
  </joint>
  <link
    name="Ankle_Cross_Left">
    <inertial>
      <origin
        xyz="-0.003722 0.000000 -0.007981"
        rpy="0 0 0" />
      <mass
        value="0.073" />
      <inertia
        ixx="0.000012"
        ixy="0.000000"
        ixz="0.000003"
        iyy="0.000029"
        iyz="0.000000"
        izz="0.000025" />
    </inertial>
    <visual>
      <origin
        xyz="0 0 0"
        rpy="0 0 0" />
      <geometry>
        <mesh
          filename="meshes/Ankle_Cross_Left.STL" />
      </geometry>
      <material
        name="">
        <color
          rgba="0.4 0.4 0.4 0.3" />
      </material>
    </visual>
  </link>
  <joint
    name="Left_Ankle_Pitch"
    type="revolute">
    <origin
      xyz="0 0 -0.28"
      rpy="0 0 0" />
    <parent
      link="Shank_Left" />
    <child
      link="Ankle_Cross_Left" />
    <axis
      xyz="0 1 0" />
    <limit
      lower="-0.87"
      upper="0.35"
      effort="24"
      velocity="12.9" />
  </joint>
  <link
    name="left_foot_link">
    <inertial>
      <origin
        xyz="-0.000249 0.000000 -0.009140"
        rpy="0 0 0" />
      <mass
        value="0.685" />
      <inertia
        ixx="0.001738"
        ixy="0.000000"
        ixz="-0.000147"
        iyy="0.002385"
        iyz="0.000000"
        izz="0.002671" />
    </inertial>
    <visual>
      <origin
        xyz="0 0 0"
        rpy="0 0 0" />
      <geometry>
        <mesh
          filename="meshes/left_foot_link.STL" />
      </geometry>
      <material
        name="">
        <color
          rgba="0.4 0.4 0.4 0.3" />
      </material>
    </visual>
    <collision>
      <origin
        xyz="0.0101079 0 -0.0214208"
        rpy="0 0 0" />
      <geometry>
        <box size="0.224868 0.1 0.04366" />
      </geometry>
    </collision>
  </link>
  <joint
    name="Left_Ankle_Roll"
    type="revolute">
    <origin
      xyz="0 0.00025 -0.012"
      rpy="0 0 0" />
    <parent
      link="Ankle_Cross_Left" />
    <child
      link="left_foot_link" />
    <axis
      xyz="1 0 0" />
    <limit
      lower="-0.44"
      upper="0.44"
      effort="15"
      velocity="12.9" />
  </joint>
  <link
    name="Hip_Pitch_Right">
    <inertial>
      <origin
        xyz="0.000534 0.007514 -0.018082"
        rpy="0 0 0" />
      <mass
        value="1.021" />
      <inertia
        ixx="0.001805"
        ixy="-0.000008"
        ixz="-0.000015"
        iyy="0.001421"
        iyz="-0.000085"
        izz="0.001292" />
    </inertial>
    <visual>
      <origin
        xyz="0 0 0"
        rpy="0 0 0" />
      <geometry>
        <mesh
          filename="meshes/Hip_Pitch_Right.STL" />
      </geometry>
      <material
        name="">
        <color
          rgba="0.76 0.76 0.76 0.2" />
      </material>
    </visual>
    <collision>
      <origin
        xyz="-0.002 0 -0.02"
        rpy="0 1.5708 0" />
      <geometry>
        <cylinder radius="0.045" length="0.085" />
      </geometry>
    </collision>
  </link>
  <joint
    name="Right_Hip_Pitch"
    type="revolute">
    <origin
      xyz="0 -0.106 0"
      rpy="0 0 0" />
    <parent
      link="Waist" />
    <child
      link="Hip_Pitch_Right" />
    <axis
      xyz="0 1 0" />
    <limit
      lower="-3.0020"
      upper="2.2166"
      effort="45"
      velocity="15.2" />
  </joint>
  <link
    name="Hip_Roll_Right">
    <inertial>
      <origin
        xyz="0.001099 0.000024 -0.053748"
        rpy="0 0 0" />
      <mass
        value="0.385" />
      <inertia
        ixx="0.001517"
        ixy="0.000000"
        ixz="0.000017"
        iyy="0.001743"
        iyz="0.000000"
        izz="0.000515" />
    </inertial>
    <visual>
      <origin
        xyz="0 0 0"
        rpy="0 0 0" />
      <geometry>
        <mesh
          filename="meshes/Hip_Roll_Right.STL" />
      </geometry>
      <material
        name="">
        <color
          rgba="0.4 0.4 0.4 0.3" />
      </material>
    </visual>
    <collision>
      <origin
        xyz="0 0 -0.11"
        rpy="0 0 0" />
      <geometry>
        <cylinder radius="0.045" length="0.08" />
      </geometry>
    </collision>
  </link>
  <joint
    name="Right_Hip_Roll"
    type="revolute">
    <origin
      xyz="0 0 -0.02"
      rpy="0 0 0" />
    <parent
      link="Hip_Pitch_Right" />
    <child
      link="Hip_Roll_Right" />
    <axis
      xyz="1 0 0" />
    <limit
      lower="-1.57"
      upper="0.2"
      effort="25"
      velocity="7.1" />
  </joint>
  <link
    name="Hip_Yaw_Right">
    <inertial>
      <origin
        xyz="-0.007191 -0.000149 -0.089220"
        rpy="0 0 0" />
      <mass
        value="2.17" />
      <inertia
        ixx="0.025137"
        ixy="0.000006"
        ixz="0.002086"
        iyy="0.025762"
        iyz="0.000044"
        izz="0.002787" />
    </inertial>
    <visual>
      <origin
        xyz="0 0 0"
        rpy="0 0 0" />
      <geometry>
        <mesh
          filename="meshes/Hip_Yaw_Right.STL" />
      </geometry>
      <material
        name="">
        <color
          rgba="0.4 0.4 0.4 0.3" />
      </material>
    </visual>
    <collision>
      <origin
        xyz="-0.015 0 -0.135"
        rpy="1.5708 0 0" />
      <geometry>
        <cylinder radius="0.055" length="0.09" />
      </geometry>
    </collision>
  </link>
  <joint
    name="Right_Hip_Yaw"
    type="revolute">
    <origin
      xyz="0 0 -0.081854"
      rpy="0 0 0" />
    <parent
      link="Hip_Roll_Right" />
    <child
      link="Hip_Yaw_Right" />
    <axis
      xyz="0 0 1" />
    <limit
      lower="-1"
      upper="1"
      effort="25"
      velocity="7.1" />
  </joint>
  <link
    name="Shank_Right">
    <inertial>
      <origin
        xyz="-0.005741 -0.000541 -0.122602"
        rpy="0 0 0" />
      <mass
        value="1.82" />
      <inertia
        ixx="0.035098"
        ixy="-0.000009"
        ixz="0.001554"
        iyy="0.034958"
        iyz="-0.000086"
        izz="0.002039" />
    </inertial>
    <visual>
      <origin
        xyz="0 0 0"
        rpy="0 0 0" />
      <geometry>
        <mesh
          filename="meshes/Shank_Right.STL" />
      </geometry>
      <material
        name="">
        <color
          rgba="0.4 0.4 0.4 0.3" />
      </material>
    </visual>
    <collision>
      <origin
        xyz="0 0 -0.15"
        rpy="0 0 0" />
      <geometry>
        <box size="0.1 0.08 0.14" />
      </geometry>
    </collision>
  </link>
  <joint
    name="Right_Knee_Pitch"
    type="revolute">
    <origin
      xyz="-0.014 0 -0.134"
      rpy="0 0 0" />
    <parent
      link="Hip_Yaw_Right" />
    <child
      link="Shank_Right" />
    <axis
      xyz="0 1 0" />
    <limit
      lower="0"
      upper="2.1817"
      effort="60"
      velocity="14.7" />
  </joint>
  <link
    name="Ankle_Cross_Right">
    <inertial>
      <origin
        xyz="-0.003722 0.000000 -0.007981"
        rpy="0 0 0" />
      <mass
        value="0.073" />
      <inertia
        ixx="0.000012"
        ixy="0.000000"
        ixz="0.000003"
        iyy="0.000029"
        iyz="0.000000"
        izz="0.000025" />
    </inertial>
    <visual>
      <origin
        xyz="0 0 0"
        rpy="0 0 0" />
      <geometry>
        <mesh
          filename="meshes/Ankle_Cross_Right.STL" />
      </geometry>
      <material
        name="">
        <color
          rgba="0.4 0.4 0.4 0.3" />
      </material>
    </visual>
  </link>
  <joint
    name="Right_Ankle_Pitch"
    type="revolute">
    <origin
      xyz="0 0 -0.28"
      rpy="0 0 0" />
    <parent
      link="Shank_Right" />
    <child
      link="Ankle_Cross_Right" />
    <axis
      xyz="0 1 0" />
    <limit
      lower="-0.87"
      upper="0.35"
      effort="24"
      velocity="12.9" />
  </joint>
  <link
    name="right_foot_link">
    <inertial>
      <origin
        xyz="-0.000248 0.000000 -0.009140"
        rpy="0 0 0" />
      <mass
        value="0.685" />
      <inertia
        ixx="0.001738"
        ixy="0.000000"
        ixz="-0.000147"
        iyy="0.002385"
        iyz="0.000000"
        izz="0.002671" />
    </inertial>
    <visual>
      <origin
        xyz="0 0 0"
        rpy="0 0 0" />
      <geometry>
        <mesh
          filename="meshes/right_foot_link.STL" />
      </geometry>
      <material
        name="">
        <color
          rgba="0.4 0.4 0.4 0.3" />
      </material>
    </visual>
    <collision>
      <origin
        xyz="0.0101079 0 -0.0214208"
        rpy="0 0 0" />
      <geometry>
        <box size="0.224868 0.1 0.04366" />
      </geometry>
    </collision>
  </link>
  <joint
    name="Right_Ankle_Roll"
    type="revolute">
    <origin
      xyz="0 -0.00025 -0.012"
      rpy="0 0 0" />
    <parent
      link="Ankle_Cross_Right" />
    <child
      link="right_foot_link" />
    <axis
      xyz="1 0 0" />
    <limit
      lower="-0.44"
      upper="0.44"
      effort="15"
      velocity="12.9" />
  </joint>
</robot>
