<mujoco model="T1">
    <compiler angle="radian" meshdir="meshes/" autolimits="true"/>
    <size njmax="500" nconmax="100" />
    <asset>
        <texture type="skybox" builtin="gradient" rgb1="0.3 0.5 0.7" rgb2="0 0 0" width="512" height="512"/>
        <texture name="texplane" type="2d" builtin="checker" rgb1=".2 .3 .4" rgb2=".1 0.15 0.2" width="512" height="512" mark="cross" markrgb=".8 .8 .8"/>
        <material name="matplane" reflectance="0.3" texture="texplane" texrepeat="1 1" texuniform="true"/>
        <mesh name="Trunk" file="Trunk.STL" />
        <mesh name="H1" file="H1.STL" />
        <mesh name="H2" file="H2.STL" />
        <mesh name="AL1" file="AL1.STL" />
        <mesh name="AL2" file="AL2.STL" />
        <mesh name="AL3" file="AL3.STL" />
        <mesh name="left_hand_link" file="left_hand_link.STL" />
        <mesh name="AR1" file="AR1.STL" />
        <mesh name="AR2" file="AR2.STL" />
        <mesh name="AR3" file="AR3.STL" />
        <mesh name="right_hand_link" file="right_hand_link.STL" />
        <mesh name="Waist" file="Waist.STL" />
        <mesh name="Hip_Pitch_Left" file="Hip_Pitch_Left.STL" />
        <mesh name="Hip_Roll_Left" file="Hip_Roll_Left.STL" />
        <mesh name="Hip_Yaw_Left" file="Hip_Yaw_Left.STL" />
        <mesh name="Shank_Left" file="Shank_Left.STL" />
        <mesh name="Ankle_Cross_Left" file="Ankle_Cross_Left.STL" />
        <mesh name="left_foot_link" file="left_foot_link.STL" />
        <mesh name="Hip_Pitch_Right" file="Hip_Pitch_Right.STL" />
        <mesh name="Hip_Roll_Right" file="Hip_Roll_Right.STL" />
        <mesh name="Hip_Yaw_Right" file="Hip_Yaw_Right.STL" />
        <mesh name="Shank_Right" file="Shank_Right.STL" />
        <mesh name="Ankle_Cross_Right" file="Ankle_Cross_Right.STL" />
        <mesh name="right_foot_link" file="right_foot_link.STL" />
        <mesh name="Logo" file="Logo.STL"/>
    </asset>
    <worldbody>
        <light directional="true" diffuse=".4 .4 .4" specular="0.1 0.1 0.1" pos="0 0 5.0" dir="0 0 -1" castshadow="false" />
        <light directional="true" diffuse=".6 .6 .6" specular="0.2 0.2 0.2" pos="0 0 4" dir="0 0 -1" />
        <geom name="ground" type="plane" pos="0 0 0" size="0 0 1" material="matplane" condim="1"/>
        <body name="Trunk" pos="0 0 0.7">
            <inertial pos="0.054281 8.47449e-06 0.0893932" quat="0.999999 -0.000254757 -0.00132228 -0.000215148" mass="19.4304" diaginertia="0.502019 0.3531 0.207324" />
            <site name='imu' size='0.01' pos='0.0 0.0 0.0' />
            <joint type="free" />
            <geom type="mesh" contype="0" conaffinity="0" group="1" density="0" rgba="0.1 0.1 0.1 1" mesh="Logo"/>
            <geom type="mesh" contype="0" conaffinity="0" group="1" rgba="0.76 0.76 0.76 1.0" mesh="Trunk" />
            <geom size="0.075 0.1 0.15" pos="0.06 0 0.12" type="box" rgba="0.76 0.76 0.76 0.0" />
            <geom pos="0.0625 0 0.243" type="mesh" contype="0" conaffinity="0" group="1" rgba="0.4 0.4 0.4 1.0" mesh="H1" />
            <geom pos="0.0625 0 0.30485" type="mesh" contype="0" conaffinity="0" group="1" rgba="0.4 0.4 0.4 1.0" mesh="H2" />
            <geom pos="0.0575 0.1063 0.219" quat="0.995004 0 0.0998334 0" type="mesh" contype="0" conaffinity="0" group="1" rgba="0.76 0.76 0.76 1.0" mesh="AL1" />
            <geom pos="0.0575 0.1533 0.219" quat="0.776807 -0.621775 0.0779406 0.0623856" type="mesh" contype="0" conaffinity="0" group="1" rgba="0.4 0.4 0.4 1.0" mesh="AL2" />
            <geom pos="0.0460173 0.16655 0.161096" quat="0.776807 -0.621775 0.0779406 0.0623856" type="mesh" contype="0" conaffinity="0" group="1" rgba="0.4 0.4 0.4 1.0" mesh="AL3" />
            <geom pos="0.0175025 0.198766 0.0204279" quat="0.768092 -0.621729 -0.078312 -0.131739" type="mesh" contype="0" conaffinity="0" group="1" rgba="0.4 0.4 0.4 1.0" mesh="left_hand_link" />
            <geom pos="0.0575 -0.1063 0.219" quat="0.995004 0 0.0998334 0" type="mesh" contype="0" conaffinity="0" group="1" rgba="0.76 0.76 0.76 1.0" mesh="AR1" />
            <geom pos="0.0575 -0.1533 0.219" quat="0.776807 0.621775 0.0779406 -0.0623856" type="mesh" contype="0" conaffinity="0" group="1" rgba="0.4 0.4 0.4 1.0" mesh="AR2" />
            <geom pos="0.0460173 -0.16655 0.161096" quat="0.776807 0.621775 0.0779406 -0.0623856" type="mesh" contype="0" conaffinity="0" group="1" rgba="0.4 0.4 0.4 1.0" mesh="AR3" />
            <geom pos="0.0175025 -0.198766 0.0204279" quat="0.768092 0.621729 -0.078312 0.131739" type="mesh" contype="0" conaffinity="0" group="1" rgba="0.4 0.4 0.4 1.0" mesh="right_hand_link" />
            <geom pos="0.0625 0 -0.1155" type="mesh" contype="0" conaffinity="0" group="1" rgba="0.4 0.4 0.4 1.0" mesh="Waist" />
            <body name="Hip_Pitch_Left" pos="0.0625 0.106 -0.1155">
                <inertial pos="0.000534 -0.007296 -0.018083" quat="0.975141 0.2211 0.0145808 0.0017406" mass="1.021" diaginertia="0.00180547 0.00145926 0.00125327" />
                <joint name="Left_Hip_Pitch" pos="0 0 0" axis="0 1 0" limited="true" range="-1.8 1.57" />
                <geom type="mesh" contype="0" conaffinity="0" group="1" rgba="0.76 0.76 0.76 1.0" mesh="Hip_Pitch_Left" />
                <body name="Hip_Roll_Left" pos="0 0 -0.02">
                    <inertial pos="0.001101 2.4e-05 -0.05375" quat="0.707081 -0.00599604 -0.00599604 0.707081" mass="0.385" diaginertia="0.001743 0.00151729 0.000514712" />
                    <joint name="Left_Hip_Roll" pos="0 0 0" axis="1 0 0" limited="true" range="-0.3 1.57" />
                    <geom type="mesh" contype="0" conaffinity="0" group="1" rgba="0.4 0.4 0.4 1.0" mesh="Hip_Roll_Left" />
                    <body name="Hip_Yaw_Left" pos="0 0 -0.081854">
                        <inertial pos="-0.007233 0.000206 -0.089184" quat="0.696808 -0.033953 -0.0315708 0.715758" mass="2.166" diaginertia="0.0257334 0.0253024 0.00259215" />
                        <joint name="Left_Hip_Yaw" pos="0 0 0" axis="0 0 1" limited="true" range="-1 1" />
                        <geom type="mesh" contype="0" conaffinity="0" group="1" rgba="0.4 0.4 0.4 1.0" mesh="Hip_Yaw_Left" />
                        <geom size="0.05 0.08" type="cylinder" rgba="0.4 0.4 0.4 0.0" />
                        <body name="Shank_Left" pos="-0.014 0 -0.134">
                            <inertial pos="-0.006012 0.000259 -0.124318" quat="0.997573 0.00144024 -0.023949 0.0653706" mass="1.82" diaginertia="0.0346951 0.0345375 0.00185844" />
                            <joint name="Left_Knee_Pitch" pos="0 0 0" axis="0 1 0" limited="true" range="0 2.34" />
                            <geom type="mesh" contype="0" conaffinity="0" group="1" rgba="0.4 0.4 0.4 1.0" mesh="Shank_Left" />
                            <geom size="0.05 0.075" pos="0 0 -0.12" type="cylinder" rgba="0.4 0.4 0.4 0.0" />
                            <body name="Ankle_Cross_Left" pos="0 0 -0.28">
                                <inertial pos="-0.003722 0 -0.007981" quat="0.443136 0.551027 0.551027 0.443136" mass="0.073" diaginertia="2.9e-05 2.56589e-05 1.13411e-05" />
                                <joint name="Left_Ankle_Pitch" pos="0 0 0" axis="0 1 0" limited="true" range="-0.87 0.35" />
                                <geom type="mesh" contype="0" conaffinity="0" group="1" rgba="0.4 0.4 0.4 0.0" mesh="Ankle_Cross_Left" />
                                <body name="left_foot_link" pos="0 0.00025 -0.012">
                                    <inertial pos="-0.000249 0 -0.00914" quat="0 0.651138 0 0.75896" mass="0.685" diaginertia="0.00269361 0.002385 0.00171539" />
                                    <joint name="Left_Ankle_Roll" pos="0 0 0" axis="1 0 0" limited="true" range="-0.44 0.44" />
                                    <geom type="mesh" contype="0" conaffinity="0" group="1" rgba="0.4 0.4 0.4 1.0" mesh="left_foot_link" />
                                    <geom size="0.1115 0.05 0.015" pos="0.01 0 -0.015" type="box" rgba="0.4 0.4 0.4 0.0" />
                                </body>
                            </body>
                        </body>
                    </body>
                </body>
            </body>
            <body name="Hip_Pitch_Right" pos="0.0625 -0.106 -0.1155">
                <inertial pos="0.000534 0.007514 -0.018082" quat="0.973446 -0.228403 0.0147148 -0.00419349" mass="1.021" diaginertia="0.00180552 0.0014632 0.00124928" />
                <joint name="Right_Hip_Pitch" pos="0 0 0" axis="0 1 0" limited="true" range="-1.8 1.57" />
                <geom type="mesh" contype="0" conaffinity="0" group="1" rgba="0.76 0.76 0.76 1.0" mesh="Hip_Pitch_Right" />
                <body name="Hip_Roll_Right" pos="0 0 -0.02">
                    <inertial pos="0.001099 2.4e-05 -0.053748" quat="0.707081 -0.00599604 -0.00599604 0.707081" mass="0.385" diaginertia="0.001743 0.00151729 0.000514712" />
                    <joint name="Right_Hip_Roll" pos="0 0 0" axis="1 0 0" limited="true" range="-1.57 0.3" />
                    <geom type="mesh" contype="0" conaffinity="0" group="1" rgba="0.4 0.4 0.4 1.0" mesh="Hip_Roll_Right" />
                    <body name="Hip_Yaw_Right" pos="0 0 -0.081854">
                        <inertial pos="-0.007191 -0.000149 -0.08922" quat="0.714468 -0.0315638 -0.0336391 0.698146" mass="2.17" diaginertia="0.0257623 0.0253298 0.00259389" />
                        <joint name="Right_Hip_Yaw" pos="0 0 0" axis="0 0 1" limited="true" range="-1 1" />
                        <geom type="mesh" contype="0" conaffinity="0" group="1" rgba="0.4 0.4 0.4 1.0" mesh="Hip_Yaw_Right" />
                        <geom size="0.05 0.08" type="cylinder" rgba="0.4 0.4 0.4 0.0" />
                        <body name="Shank_Right" pos="-0.014 0 -0.134">
                            <inertial pos="-0.005741 -0.000541 -0.122602" quat="0.99926 -0.000580963 -0.023461 -0.0304754" mass="1.82" diaginertia="0.0351717 0.0349574 0.00196589" />
                            <joint name="Right_Knee_Pitch" pos="0 0 0" axis="0 1 0" limited="true" range="0 2.34" />
                            <geom type="mesh" contype="0" conaffinity="0" group="1" rgba="0.4 0.4 0.4 1.0" mesh="Shank_Right" />
                            <geom size="0.05 0.075" pos="0 0 -0.12" type="cylinder" rgba="0.4 0.4 0.4 0.0" />
                            <body name="Ankle_Cross_Right" pos="0 0 -0.28">
                                <inertial pos="-0.003722 0 -0.007981" quat="0.443136 0.551027 0.551027 0.443136" mass="0.073" diaginertia="2.9e-05 2.56589e-05 1.13411e-05" />
                                <joint name="Right_Ankle_Pitch" pos="0 0 0" axis="0 1 0" limited="true" range="-0.87 0.35" />
                                <geom type="mesh" contype="0" conaffinity="0" group="1" rgba="0.4 0.4 0.4 1.0" mesh="Ankle_Cross_Right" />
                                <body name="right_foot_link" pos="0 -0.00025 -0.012">
                                    <inertial pos="-0.000248 0 -0.00914" quat="0 0.651138 0 0.75896" mass="0.685" diaginertia="0.00269361 0.002385 0.00171539" />
                                    <joint name="Right_Ankle_Roll" pos="0 0 0" axis="1 0 0" limited="true" range="-0.44 0.44" />
                                    <geom type="mesh" contype="0" conaffinity="0" group="1" rgba="0.4 0.4 0.4 1.0" mesh="right_foot_link" />
                                    <geom size="0.1115 0.05 0.015" pos="0.01 0 -0.015" type="box" rgba="0.4 0.4 0.4 0.0" />
                                </body>
                            </body>
                        </body>
                    </body>
                </body>
            </body>
        </body>
    </worldbody>
    <actuator>
    <motor name="Left_Hip_Pitch" joint="Left_Hip_Pitch" forcerange="-45.0 45.0"/>
    <motor name="Left_Hip_Roll" joint="Left_Hip_Roll" forcerange="-25.0 25.0"/>
    <motor name="Left_Hip_Yaw" joint="Left_Hip_Yaw" forcerange="-25.0 25.0"/>
    <motor name="Left_Knee_Pitch" joint="Left_Knee_Pitch" forcerange="-60.0 60.0"/>
    <motor name="Left_Ankle_Pitch" joint="Left_Ankle_Pitch" forcerange="-24.0 24.0"/>
    <motor name="Left_Ankle_Roll" joint="Left_Ankle_Roll" forcerange="-15.0 15.0"/>
    <motor name="Right_Hip_Pitch" joint="Right_Hip_Pitch" forcerange="-45.0 45.0"/>
    <motor name="Right_Hip_Roll" joint="Right_Hip_Roll" forcerange="-25.0 25.0"/>
    <motor name="Right_Hip_Yaw" joint="Right_Hip_Yaw" forcerange="-25.0 25.0"/>
    <motor name="Right_Knee_Pitch" joint="Right_Knee_Pitch" forcerange="-60.0 60.0"/>
    <motor name="Right_Ankle_Pitch" joint="Right_Ankle_Pitch" forcerange="-24.0 24.0"/>
    <motor name="Right_Ankle_Roll" joint="Right_Ankle_Roll" forcerange="-15.0 15.0"/>
        </actuator>
    <sensor>
        <framequat name="orientation" objtype="site" noise="0.001" objname="imu" />
        <gyro name="angular-velocity" site="imu" noise="0.005" />
    </sensor>
</mujoco>
